<?xml version="1.0"?>
<robot name="sainsmart_6dof">

    <!-- Base Link -->
    <link name="base_link"/>
    
    <!-- Joint 1 (Rotating Base) -->
    <joint name="joint_1" type="revolute">
        <parent link="base_link"/>
        <child link="link_1"/>
        <origin xyz="0 0 0" rpy="0 0 0"/>
        <axis xyz="0 0 1"/>
        <limit effort="5.0" velocity="1.0" lower="-3.14" upper="3.14"/>
    </joint>
    
    <link name="link_1">
        <visual>
            <geometry>
                <cylinder radius="0.03" length="0.07"/>
            </geometry>
        </visual>
    </link>

    <!-- Joint 2 -->
    <joint name="joint_2" type="revolute">
        <parent link="link_1"/>
        <child link="link_2"/>
        <origin xyz="0 0 0.07" rpy="0 0 0"/>
        <axis xyz="0 1 0"/>
        <limit effort="5.0" velocity="1.0" lower="-1.57" upper="1.57"/>
    </joint>
    
    <link name="link_2">
        <visual>
            <geometry>
                <cylinder radius="0.025" length="0.12"/>
            </geometry>
        </visual>
    </link>

    <!-- Joint 3 -->
    <joint name="joint_3" type="revolute">
        <parent link="link_2"/>
        <child link="link_3"/>
        <origin xyz="0 0 0.12" rpy="0 0 0"/>
        <axis xyz="0 1 0"/>
        <limit effort="5.0" velocity="1.0" lower="-1.57" upper="1.57"/>
    </joint>
    
    <link name="link_3">
        <visual>
            <geometry>
                <cylinder radius="0.02" length="0.085"/>
            </geometry>
        </visual>
    </link>
    
  <joint name="joint_4" type="revolute">
    <parent link="link_3"/>
    <child link="link_4"/>
    <origin xyz="0 0 0.085" rpy="0 0 0"/>
    <axis xyz="0 0 1"/>  <!-- Rotation around the Z-axis -->
    <limit effort="1.0" velocity="1.0" lower="-1.57" upper="1.57"/>
  </joint>

    
    <link name="link_4">
        <visual>
            <geometry>
                <sphere radius="0.02"/>
            </geometry>
        </visual>
    </link>
    
    <!-- Joint 5 -->
    <joint name="joint_5" type="revolute">
        <parent link="link_4"/>
        <child link="link_5"/>
        <origin xyz="0 0 0" rpy="0 0 0"/>
        <axis xyz="0 1 0"/>
        <limit effort="5.0" velocity="1.0" lower="-1.57" upper="1.57"/>
    </joint>
    
    <link name="link_5">
        <visual>
            <geometry>
                <cylinder radius="0.015" length="0.03"/>
            </geometry>
        </visual>
    </link>
    
    <!-- Joint 6 (End Effector) -->
    <joint name="joint_6" type="revolute">
        <parent link="link_5"/>
        <child link="end_effector"/>
        <origin xyz="0 0 0.03" rpy="0 0 0"/>
        <axis xyz="0 0 1"/>
        <limit effort="5.0" velocity="1.0" lower="-3.14" upper="3.14"/>
    </joint>
    
    <link name="end_effector">
        <visual>
            <geometry>
                <sphere radius="0.02"/>
            </geometry>
        </visual>
    </link>
    
</robot>
